2021-06-08 18:16:37,289 dellemc_isilon_gatherfacts.py INFO : Got python SDK instance for provisioning on Isilon 
2021-06-08 18:18:47,013 connectionpool.py WARNING : Retrying (Retry(total=2, connect=None, read=None, redirect=None, status=None)) after connection broken by 'NewConnectionError('<urllib3.connection.VerifiedHTTPSConnection object at 0x7f41f6dc4a90>: Failed to establish a new connection: [Errno 110] Connection timed out',)': /session/1/session
2021-06-08 18:20:58,085 connectionpool.py WARNING : Retrying (Retry(total=1, connect=None, read=None, redirect=None, status=None)) after connection broken by 'NewConnectionError('<urllib3.connection.VerifiedHTTPSConnection object at 0x7f41f6dc4ba8>: Failed to establish a new connection: [Errno 110] Connection timed out',)': /session/1/session
2021-06-08 18:23:09,157 connectionpool.py WARNING : Retrying (Retry(total=0, connect=None, read=None, redirect=None, status=None)) after connection broken by 'NewConnectionError('<urllib3.connection.VerifiedHTTPSConnection object at 0x7f41f68ef0f0>: Failed to establish a new connection: [Errno 110] Connection timed out',)': /session/1/session
2021-06-08 18:25:20,229 dellemc_isilon_gatherfacts.py ERROR : Get Attributes List for Isilon cluster: 192.168.3.11 failed with error: HTTPSConnectionPool(host='192.168.3.11', port=8080): Max retries exceeded with url: /session/1/session (Caused by NewConnectionError('<urllib3.connection.VerifiedHTTPSConnection object at 0x7f41f68fb128>: Failed to establish a new connection: [Errno 110] Connection timed out',))
